Workbook

Sheet Assumptions
B2: Leep AI — $50K Collected in December 2026
B3: Up-market, multi-channel model. Supersedes the exit-run-rate model in 50k-mrr-funnel-model.xlsx
B5: EDIT ONLY THE YELLOW CELLS. Blue text = input. Black = formula. Green = pulled from another sheet.
B7: THE GOAL
B8: Input | C8: Value | F8: Source / note
B9: Target COLLECTED revenue, December | C9: 50000 | F9: Collected, not exit run-rate. Contracts must be billing by 1 Dec.
B10: Current MRR | C10: 3500 | F10: Aaron: $3-4K/mo. Midpoint used.
B11: Incremental MRR required | C11: =MAX(0,C9-C10)
B12: Months to the SIGNATURE deadline | C12: 3.8 | F12: 30 Nov, not 31 Dec. Collected revenue needs contracts billing by 1 Dec.
B14: DEAL ECONOMICS — BARBELL: two segments
B15: Group tier carries the revenue. Fast tier de-risks the 30 Nov deadline with a shorter cycle.
B16: Input | C16: Value | F16: Source / note
B17: GROUP tier — customers | C17: 5 | F17: 3-8 location med spa groups. 30-90 day cycle.
B18: GROUP tier — ACV per month | C18: 4500 | F18: Below the mid-market agency floor of $5,000 with more scope.
B19: FAST tier — customers | C19: 12 | F19: Single-location HVAC, plumbing LEADERS only, med spa $1.5M+. 14-45 day cycle.
B20: FAST tier — ACV per month | C20: 2000 | F20: Month-to-month, one decision maker, runs in their existing stack.
B21: Total customers | C21: =C17+C19
B22: New MRR from both tiers | C22: =C17*C18+C19*C20
B23: Blended ACV per month | C23: =IF(C21<=0,0,C22/C21)
B24: Gross margin | C24: 0.65
B25: Covers the gap? | C25: =IF(C22>=C11,"YES","SHORT")
B26: Projected December collected | C26: =C10+C22
B28: CHANNEL MIX — how the customers are sourced
B29: Channel | C29: Customers | F29: Rationale
B30: From outbound | C30: 9 | F30: Proven, controllable. Does not depend on unvalidated CPL.
B31: From paid ads | C31: 5 | F31: Real upside, sub-month payback, but only $303 of history. Gate the spend.
B32: From referral / existing base | C32: 3 | F32: Cheapest revenue available and currently unassigned to anyone.
B33: Total sourced | C33: =SUM(C30:C32)
B34: Matches total customers? | C34: =IF(C33>=C21,"COVERED","SHORT")
B36: OUTBOUND CONVERSION RATES
B37: Stage | C37: Model | D37: Bench avg | E37: Top qtile | F37: Source
B38: Dial to live connect | C38: 0.2 | D38: 0.1 | E38: 0.22 | F38: Generic data 8-12%; verified mobile direct-dial 18-22%. Gong avg 5.4%, top qtile 13.3%.
B39: Connect to meeting (set rate) | C39: 0.15 | D39: 0.046 | E39: 0.167 | F39: Gong 300M+ calls: avg 4.6%, top quartile 16.7%.
B40: Meeting to qualified opp | C40: 0.6 | D40: 0.5 | E40: 0.7 | F40: Not benchmarked. Signal-qualified should beat generic.
B41: Qualified opp to close | C41: 0.27 | D41: 0.24 | E41: 0.35 | F41: $10-50K ACV: 20-28%. Sub-$10K: 28-35%. Above 40% sustained means underpriced.
B43: PAID ADS
B44: Input | C44: Value | F44: Source / note
B45: Cost per lead | C45: 125 | F45: B2B avg $63.40; qualified $150-250. Your $1.21 was a different offer with instant forms.
B46: Lead to customer conversion | C46: 0.05 | F46: Professional services 4.6% (highest B2B category). Inbound 5-10%, outbound 1-3%.
B47: Implied CAC from ads | C47: =IF(C46<=0,0,C45/C46)
...

Sheet Activity
B2: Activity Requirements
B3: Dials, emails and SMS needed, worked backwards from the outbound customer target.
B5: OUTBOUND FUNNEL
B6: Stage | C6: Per month | D6: Whole period | E6: Conv rate | F6: Note
B7: Closes from outbound | C7: =IF(Assumptions!C12<=0,0,Assumptions!C30/Assumptions!C12) | D7: =Assumptions!C30
B8: Qualified opportunities | C8: =IF(Assumptions!C41<=0,0,C7/Assumptions!C41) | D8: =C8*Assumptions!C12 | E8: =Assumptions!C41
B9: Meetings booked | C9: =IF(Assumptions!C40<=0,0,C8/Assumptions!C40) | D9: =C9*Assumptions!C12 | E9: =Assumptions!C40
B10: Live connects | C10: =IF(Assumptions!C39<=0,0,C9/Assumptions!C39) | D10: =C10*Assumptions!C12 | E10: =Assumptions!C39
B11: DIALS REQUIRED | C11: =IF(Assumptions!C38<=0,0,C10/Assumptions!C38) | D11: =C11*Assumptions!C12 | E11: =Assumptions!C38
B13: CHANNEL VOLUMES
B14: Channel | C14: Per month | D14: Per day | E14: Limit | F14: Status
B15: Dials | C15: =C11 | D15: =IF(Assumptions!C56<=0,0,C15/Assumptions!C56) | E15: =Assumptions!C57*Assumptions!C55 | F15: =IF(D15<=E15,"OK","OVER CAPACITY")
B16: dials per person per day | D16: =IF(Assumptions!C55<=0,0,D15/Assumptions!C55) | E16: =Assumptions!C57 | F16: =IF(D16<=E16,"OK","OVER CAPACITY")
B17: Emails | C17: =C11*Assumptions!C52 | D17: =IF(Assumptions!C56<=0,0,C17/Assumptions!C56) | E17: =Assumptions!C58 | F17: =IF(D17<=E17,"OK","BULK SENDER RISK")
B18: Consented prospects | C18: =C10*Assumptions!C53 | F18: Written opt-in captured after a live call. The SMS gate.
B19: SMS | C19: =C18*Assumptions!C54 | D19: =IF(Assumptions!C56<=0,0,C19/Assumptions!C56) | F19: Consented only. Zero TCPA exposure. ~45% response vs ~6% for email.
B21: EXPECTED RESPONSES
B22: Channel | C22: Volume/mo | D22: Rate | E22: Responses/mo | F22: Source
B23: Email replies | C23: =C17 | D23: 0.0343 | E23: =C23*D23 | F23: 2026 B2B cold email: 27.7% open, 3.43% reply. Above 5% beats most senders.
B24: SMS responses | C24: =C19 | D24: 0.45 | E24: =C24*D24 | F24: Opted-in SMS averages ~45%. Qualifying questions reach 92%.
B26: Note: SMS is a fraction of email volume and produces comparable response counts. That is why the consent gate is an asset, not a tax.

Sheet Paid Ads
B2: Paid Ads — Reverse-Engineered Spend
B3: Modelled on B2B benchmarks, NOT on the account's historical $1.21 CPL. See the warning below.
B5: YOUR ACTUAL ACCOUNT — pulled 7 Aug 2026, account 1819763081734046
B6: Metric | C6: Your account | D6: B2B benchmark | F6: Read
B7: Total spend, all time | C7: $303.02 | D7: - | F7: A test, not a programme
B8: Campaigns | C8: 3, ALL PAUSED | D8: - | F8: Nothing is running today
B9: CTR | C9: 5.31% | D9: ~1% | F9: GENUINELY EXCELLENT. The hook works
B10: CPC | C10: $0.40 | D10: $2.96 avg search | F10: Cheap traffic
B11: CPM | C11: $21.10 | D11: - | F11: Reasonable
B12: Leads | C12: 251 | D12: - | F12: 763 clicks to 251 leads = 33%, an instant-form signature
B13: Cost per lead | C13: $1.21 | D13: $63.40 B2B | F13: 52x below benchmark. Different offer entirely
B15: CRITICAL: the $1.21 CPL came from a campaign named 'Leads offer', not from the AI receptionist offer.
B16: The two campaigns matching this business - 'AI Receptionist VSL - Automotive' and 'automotive ads V2' - have ZERO recorded spend.
B17: There is no validated cost-per-lead for the offer you intend to scale. Model at $125-200 and be delighted to beat it.
B19: UNIT ECONOMICS
B20: Scenario | C20: CPL | D20: Lead to cust | E20: CAC | F20: Payback, months of ACV
B21: Conservative | C21: 200 | D21: 0.03 | E21: =IF(D21<=0,0,C21/D21) | F21: =IF(Assumptions!$C$23<=0,0,E21/Assumptions!$C$23)
B22: BASE | C22: 125 | D22: 0.05 | E22: =IF(D22<=0,0,C22/D22) | F22: =IF(Assumptions!$C$23<=0,0,E22/Assumptions!$C$23)
B23: Optimistic | C23: 63 | D23: 0.07 | E23: =IF(D23<=0,0,C23/D23) | F23: =IF(Assumptions!$C$23<=0,0,E23/Assumptions!$C$23)
B25: SPEND REQUIRED
B26: Customers from ads | C26: Leads needed | D26: Spend at base CPL | E26: Spend at $200 CPL | F26: Note
B27: 3 | C27: =IF(Assumptions!$C$46<=0,0,B27/Assumptions!$C$46) | D27: =C27*Assumptions!$C$45 | E27: =C27*200
B28: 4 | C28: =IF(Assumptions!$C$46<=0,0,B28/Assumptions!$C$46) | D28: =C28*Assumptions!$C$45 | E28: =C28*200 | F28: << Planned channel mix
B29: 6 | C29: =IF(Assumptions!$C$46<=0,0,B29/Assumptions!$C$46) | D29: =C29*Assumptions!$C$45 | E29: =C29*200
B30: 9 | C30: =IF(Assumptions!$C$46<=0,0,B30/Assumptions!$C$46) | D30: =C30*Assumptions!$C$45 | E30: =C30*200
B31: 12 | C31: =IF(Assumptions!$C$46<=0,0,B31/Assumptions!$C$46) | D31: =C31*Assumptions!$C$45 | E31: =C31*200 | F31: All from ads. Do not bet the quarter on an unvalidated channel
B33: Planned total ad spend | C33: =IF(Assumptions!C46<=0,0,Assumptions!C31/Assumptions!C46*Assumptions!C45)
B34: Planned monthly ad spend | C34: =IF(Assumptions!C12<=0,0,C33/Assumptions!C12)
B36: STAGED ROLLOUT — gate the spend
B37: Stage | C37: Spend | D37: Purpose | F37: Gate to proceed
B38: Validate (Aug) | C38: 1500 | D38: Restart the AI Receptionist campaigns that never spent. Prove CPL for the REAL offer | F38: CPL under $200 AND at least 1 booked meeting from 12 leads
B39: Calibrate (Sep) | C39: 3000 | D39: Test offer angles and audiences. Measure lead-to-meeting, not just CPL | F39: Lead to meeting above 10%
B40: Scale (Oct-Nov) | C40: 4000 | D40: Push spend on the winner, monthly | F40: CAC under 1.5 months of ACV
B41: Retargeting (throughout) | C41: ~15% | D41: Run ads AT the outbound list. Warms every dial | F41: ~15% of total spend
B43: Highest-leverage play: retarget the outbound list. Multi-channel sequences beat single-channel by 3-4x; email plus phone lifts engagement 287%.

Sheet Up-Market Pricing
B2: Up-Market Pricing vs Competition
B3: You are underpriced against your own client size, not against AI tools.
B5: THE COMPETITIVE SET — what a 5-location med spa group pays today
B6: Who | C6: What they deliver | D6: Low | E6: High | F6: Source
B7: Self-serve AI tools | C7: One AI receptionist, DIY setup | D7: 25 | E7: 95 | F7: cloudtalk.io, voksha.com
B8: Voice AI resellers | C8: AI receptionist, per location | D8: 295 | E8: 595 | F8: trillet.ai
B9: Voice AI, multi-location | C9: Receptionist across sites | D9: 750 | E9: 1200 | F9: trillet.ai
B10: Managed voice, high-ticket | C10: Managed outbound programme | D10: 797 | E10: 1497 | F10: ringlyn.com
B11: Multi-location SEO specialist | C11: SEO only, comprehensive | D11: 3000 | E11: 6000 | F11: clicksgeek.com
B12: Mid-market agency | C12: SEO + content + paid. NO AI | D12: 5000 | E12: 15000 | F12: fbd.agency
B13: Enterprise agency | C13: Multi-channel, dedicated team | D13: 15000 | E13: 50000 | F13: fbd.agency
B14: LEEP AI, doc 03 thinking | C14: Voice + SMS + chat + SEO + CRM hygiene | D14: 2500 | E14: 2500 | F14: More scope than a mid-market agency, at HALF the price of SEO alone
B16: THE UP-MARKET LADDER
B17: Tier | C17: Scope | D17: Price/mo | E17: GP per year | F17: Benchmarked against
B18: Core | C18: Voice + reactivation, 1-2 locations | D18: 2000 | E18: =D18*12*Assumptions!$C$24 | F18: Above multi-location voice ($750+)
B19: Group | C19: Full stack, 3-8 locations | D19: 5000 | E19: =D19*12*Assumptions!$C$24 | F19: Low end of mid-market agency ($5-15K)
B20: Value-event | C20: Group + diligence data work, pre-exit | D20: 8000 | E20: =D20*12*Assumptions!$C$24 | F20: Mid-market, justified by EBITDA math
B21: Enterprise-lite | C21: 8-15 locations, multi-brand | D21: 12000 | E21: =D21*12*Assumptions!$C$24 | F21: Bottom of the enterprise band
B24: THE TENSION — up-market raises ACV but lowers close rate and lengthens the cycle
B25: With a 30 November signature deadline, cycle length is the binding constraint.
B26: ACV/mo | C26: Annual | D26: Close rate band | E26: Cycle | F26: Customers needed / verdict
B27: 2500 | C27: =B27*12 | D27: 20-28% | E27: 30-90d | F27: =ROUNDUP(Assumptions!$C$11/B27,0)&" customers — Underpriced, high volume"
B28: 4000 | C28: =B28*12 | D28: 20-28% | E28: 30-90d | F28: =ROUNDUP(Assumptions!$C$11/B28,0)&" customers — SWEET SPOT"
B29: 6000 | C29: =B29*12 | D29: 15-22% | E29: 30-90d+ | F29: =ROUNDUP(Assumptions!$C$11/B29,0)&" customers — Strong, slower"
B30: 8000 | C30: =B30*12 | D30: 15-22% | E30: 60-120d | F30: =ROUNDUP(Assumptions!$C$11/B30,0)&" customers — Cycle likely overruns 30 Nov"
B31: 12000 | C31: =B31*12 | D31: 12-18% | E31: 90-180d | F31: =ROUNDUP(Assumptions!$C$11/B31,0)&" customers — Cannot close in time"
B33: Recommendation: $4,000/mo blended, Group tier listed $4,000-6,000. Keeps you in the 20-28% close band and a 30-90 day cycle, so two cohorts fit before 30 Nov.
B34: $8,000+ is the right 2027 position and the wrong bet for a November deadline.

Sheet Timeline
B2: Timeline
B3: Collected revenue moves the deadline to 30 November and the build deadline to ~1 September.
B5: WHAT 'COLLECTED' COSTS YOU
B6: Milestone | C6: Exit run-rate (doc 03) | D6: COLLECTED (actual) | E6: Impact
B7: Signature deadline | C7: 31 Dec | D7: ~30 Nov | E7: One month lost
B8: Time from today | C8: 4.8 months | D8: 3.8 months | E8: 21% less selling time
B9: Pipeline created by | C9: 1 Oct - 1 Dec | D9: 1 Sep - 31 Oct | E9: Cohort one starts now
B10: Engine live by | C10: 1 Oct | D10: ~1 Sep | E10: FOUR WEEKS FROM TODAY
B13: MONTH BY MONTH
B14: Month | C14: Focus | D14: Must be true by month end | E14: Ad spend
B15: August | C15: Build + validate | D15: Engine live. Domain warming. AI receptionist ads restarted and CPL measured | E15: $1,500
B16: September | C16: Pilot + first cohort | D16: Real conversion numbers measured. First deals in pipeline. Ads calibrated | E16: $3,000
B17: October | C17: Full volume | D17: Pipeline arithmetic supports the target. BUILD FROZEN | E17: $4,000
B18: November | C18: CLOSE | D18: All 12 signed by 30 Nov. Billing configured for 1 Dec | E18: $4,000
B19: December | C19: Collect + deliver | D19: $50K collected. Delivery capacity is now the constraint | E19: Maintain
B22: THIS WEEK — non-negotiable
B23: 1. | C23: Buy the prospecting domain and start warmup. A new domain needs 4-8 weeks to reach 50 emails/day. Confirm the spelling first (itsleapai vs itsleepai).
B24: 2. | C24: Restart the AI Receptionist ad campaigns at $50/day. You need a real CPL for the real offer before you can plan around ads at all.
B25: 3. | C25: Assign referral outreach to a named person. Two referrals at $4,000 is $8,000/mo for effectively zero CAC and nobody owns it.
B26: 4. | C26: Decide the Group tier price. Everything downstream depends on it.
B27: 5. | C27: Start recording every cold call. It is the training data and it is unrecoverable once a call happens.

Sheet Industry Profiles
B2: Industry Economics
B3: Every figure sourced. See 05-industry-icp-fast-market.md for citations.
B5: Metric | C5: HVAC | D5: Plumbing | E5: Med Spa | F5: Auto Detailing | G5: Note
B6: Typical revenue | C6: $750K-1.5M | D6: $1.28M avg | E6: $1.86M median | F6: ~$168K mobile | G6: Med spa leads by a wide margin
B7: Average employees | C7: 5.2 | D7: 5 | E7: n/a | F7: 1-5 | G7: All owner-operator scale
B8: Average ticket | C8: $1,400-1,800 | D8: $150-500 | E8: $450-600/visit | F8: $185 | G8: Ticket drives the ROI story
B9: Customer LTV | C9: $15,340 | D9: n/a | E9: $1,800-5,200 | F9: n/a | G9: HVAC LTV is exceptional
B10: Net margin | C10: 8-12% | D10: 2-8% median / 20-35% leaders | E10: est. 15-25% | F10: 12.5-30% | G10: Plumbing is bimodal
B11: Monthly profit | C11: $5K-15K | D11: $2K-8.5K / $21K-37K | E11: $23K-39K | F11: $2.1K-4.2K | G11: This is the affordability line
B12: $2,000 retainer as % profit | C12: 13-40% | D12: 24-94% / 5-10% | E12: 5-9% | F12: 48-95% | G12: Under 15% is comfortable
B13: US business count | C13: n/a | D13: 113,347 | E13: 10,000+ locations | F13: 16,879 incl. car wash | G13: TAM check
B14: AFFORDABILITY VERDICT | C14: NEEDS ROI CASE | D14: LEADERS ONLY | E14: COMFORTABLE | F14: CANNOT AFFORD | G14: Retainer vs monthly profit
B15: Q4 SEASONAL FIT | C15: EXCELLENT | D15: GOOD | E15: EXCELLENT | F15: POOR - off season | G15: You sell Aug-Nov. Timing is a filter, not a footnote.
B17: ENTRY PLAYBOOK
B18: Industry | C18: Lead product | E18: Top 3 pain signals | G18: Expected ticket
B19: HVAC | C19: Voice AI receptionist | E19: 1. Main line rings to mobile or voicemail in posted hours 2. Receptionist posting live 30+ days 3. Reviews citing 'never called back' | G19: $1,500-2,500
B20: Plumbing | C20: Voice AI, after-hours wedge | E20: 1. Advertises 24/7 but off-hours call fails 2. Answering service in use (price anchor) 3. Paid ads running to a slow-response number | G20: $1,500-2,500
B21: Med Spa | C21: SMS reactivation. NOT voice | E21: 1. On Boulevard (weak attribution + LTV reporting) 2. Review count far exceeds recent velocity 3. No email or SMS marketing footprint | G21: $2,000-3,000 single / $4,000-6,000 group
B22: Auto Detailing | C22: DEPRIORITISE this quarter | E22: Fails on affordability AND Q4 seasonality. Keep the accounts and products; revisit in spring. | G22: n/a
B24: HVAC: each missed call costs $350+; 5 missed calls a week is $91,000 a year. Published in their own trade press. Your single best sales asset.

Sheet Strategy Compare
B2: Up-Market vs Fast-Market vs Barbell
B3: Same gap to close. Three routes. The barbell hedges the 30 November deadline.
B5: Dimension | C5: Up-market | D5: Fast-market | E5: BARBELL | F5: Why it matters
B6: Blended ACV | C6: $4,000 | D6: $2,250 | E6: $2,735 | F6: Price is the biggest lever on funnel volume
B7: Customers needed | C7: 12 | D7: 21 | E7: 17 | F7: Each one consumes delivery capacity
B8: Typical cycle | C8: 30-90 days | D8: 14-45 days | E8: Mixed | F8: Cycle, not revenue, is the binding constraint
B9: Cohorts before 30 Nov | C9: ~2 | D9: ~4 | E9: 2 slow + 4 fast | F9: More shots on goal
B10: Close rate band | C10: 20-28% | D10: 25-35% | E10: Mixed | F10: Smaller simpler decisions close better
B11: Dials/month, outbound | C11: 356 | D11: ~800 | E11: ~600 | F11: Two callers at 40/day sustainable
B12: Main risk | C12: Deals slip past 30 Nov | D12: Volume strain on 2 callers | E12: Diversified | F12: The barbell fails more gracefully
B15: THE BARBELL, COMPOSED
B16: Segment | C16: Customers | D16: ACV/mo | E16: MRR | F16: Who
B17: Group tier | C17: =Assumptions!C17 | D17: =Assumptions!C18 | E17: =C17*D17 | F17: 3-8 location med spa groups
B18: Fast tier | C18: =Assumptions!C19 | D18: =Assumptions!C20 | E18: =C18*D18 | F18: Single-location HVAC, plumbing LEADERS, med spa $1.5M+
B19: Total new MRR | C19: =SUM(C17:C18) | E19: =SUM(E17:E18)
B20: Plus current MRR | E20: =Assumptions!C10
B21: DECEMBER COLLECTED | E21: =E19+E20
B23: WHAT MAKES THE FAST TIER ACTUALLY FAST
B24: Lowering price does NOT shorten the cycle on its own. Engineer these or you get a small deal on a long cycle.
B25: • | C25: Month-to-month. No annual contract. Removes the biggest deliberation trigger.
B26: • | C26: One decision maker, always. Filter hard on owner-operator markers.
B27: • | C27: Runs inside their existing software. No migration means no IT conversation.
B28: • | C28: Published pricing. Negotiation adds weeks; a firm number closes.
B29: • | C29: Two calls maximum: diagnosis then proposal. A third call means it is a Group deal.
B30: • | C30: Time-to-value under 14 days. They test cheaply instead of deliberating expensively.
